
2018-06-12 14:06:32,525 Process Simplify ERROR   meshlab stl to obj creation error
2018-06-12 14:06:32,526 Process Simplify ERROR   Traceback (most recent call last):
  File "/app/Simplify.py", line 46, in simplify
    stl_to_obj(mesh_path, tmp_obj_path, meshlab_command, os.path.join(simplify_path, "remove_duplicated_vertex.mlx"))
  File "/app/utils.py", line 111, in stl_to_obj
    raise ValueError("meshlab stl to obj creation error")
ValueError: meshlab stl to obj creation error

During handling of the above exception, another exception occurred:

Traceback (most recent call last):
  File "/app/utils.py", line 193, in run
    result = self.perform(*args)
  File "/app/utils.py", line 301, in perform
    out_file, mesh_name, verbose, P2Slice_path, tmp_path, meshlab_command, logging=self.logger)
  File "/app/Simplify.py", line 49, in simplify
    raise_simplify_error()
  File "/app/Simplify.py", line 80, in raise_simplify_error
    raise ValueError("Simplify Error")
ValueError: Simplify Error

2018-06-12 14:33:46,866 Process Simplify ERROR   meshlab stl to obj creation error
2018-06-12 14:33:46,870 Process Simplify ERROR   Traceback (most recent call last):
  File "/app/Simplify.py", line 46, in simplify
    stl_to_obj(mesh_path, tmp_obj_path, meshlab_command, os.path.join(simplify_path, "remove_duplicated_vertex.mlx"))
  File "/app/utils.py", line 111, in stl_to_obj
    raise ValueError("meshlab stl to obj creation error")
ValueError: meshlab stl to obj creation error

During handling of the above exception, another exception occurred:

Traceback (most recent call last):
  File "/app/utils.py", line 193, in run
    result = self.perform(*args)
  File "/app/utils.py", line 301, in perform
    out_file, mesh_name, verbose, P2Slice_path, tmp_path, meshlab_command, logging=self.logger)
  File "/app/Simplify.py", line 49, in simplify
    raise_simplify_error()
  File "/app/Simplify.py", line 80, in raise_simplify_error
    raise ValueError("Simplify Error")
ValueError: Simplify Error

2018-06-12 14:39:55,810 Process Clean File ERROR   Traceback (most recent call last):
  File "/app/utils.py", line 198, in run
    result = self.perform(*args)
  File "/app/utils.py", line 420, in perform
    if (os.path.getsize(original_mesh_path) < 100):
  File "/usr/lib64/python3.4/genericpath.py", line 50, in getsize
    return os.stat(filename).st_size
FileNotFoundError: [Errno 2] No such file or directory: './p2slice_test/files-fish-fossilz.stl'

2018-06-12 14:41:13,731 Process Clean File ERROR   Traceback (most recent call last):
  File "/app/utils.py", line 198, in run
    result = self.perform(*args)
  File "/app/utils.py", line 420, in perform
    if (os.path.getsize(original_mesh_path) < 100):
  File "/usr/lib64/python3.4/genericpath.py", line 50, in getsize
    return os.stat(filename).st_size
FileNotFoundError: [Errno 2] No such file or directory: './p2slice_test/files-fish-fossilz.stl'

